Workbook
Name __G90000: #REF!
Name _1_0DAI: #REF!
Name _10R: #REF!
Name _2DAI: #REF!
Name _3_0P: #REF!
Name _4P: #REF!
Name _5_?_0P: #REF!
Name _6_?__P: #REF!
Name _7_0P: #REF!
Name _8_0R: #REF!
Name _9P: #REF!
Name _G90000: #REF!
Name _G900000: #REF!
Name _PRG1: #REF!
Name _PRG2: #REF!
Name _PRG3: #REF!
Name _PRG31: #REF!
Name _PRG4: #REF!
Name _PRG5: #REF!
Name _RPG4: #REF!
Name _VSA1: #REF!
Name _VSA2: #REF!
Name _vsa3: #REF!
Name aaa: #REF!
Name ASFIII: #REF!
Name AUM: #REF!
Name AUMCheck: #REF!
Name AUMCurrency: #REF!
Name Baselinedata: #REF!
Name bis: #REF!
Name biz: #REF!
Name BoardDate: #REF!
Name Carlyle1: #REF!
Name Carlyle2: #REF!
Name carlyle3: #REF!
Name Cashflows: #REF!
Name Client_GainLoss: #REF!
Name ClientsCheck: #REF!
Name ClientType: #REF!
Name closingdate: #REF!
Name closingdateexample: #REF!
Name COL_C_C_ACTIVITY: #REF!
Name COL_C_C_COMMENT: #REF!
Name COL_C_C_CREATION_DATE: #REF!
Name COL_C_C_CURRENCY: #REF!
Name COL_C_C_EFRONTFORMULAPARAM1: #REF!
Name COL_C_C_EFRONTFORMULAPARAM2: #REF!
Name COL_C_C_FUNDING: #REF!
Name COL_C_C_ID: #REF!
Name COL_C_C_INV_MANAGER: #REF!
Name COL_C_C_NAME: #REF!
Name COL_C_C_NOMINAL_VALUE: #REF!
Name COL_C_C_NOMINAL_VALUE_CURRENCY: #REF!
Name COL_C_C_NR_SHARES_FD: #REF!
Name COL_C_C_NR_SHARES_FD_OBSOLETE: #REF!
Name COL_C_C_NR_SHARES_NFD: #REF!
Name COL_C_ID1: #REF!
Name COL_CF_CF_EXIT_CCY: #REF!
Name COL_CF_CF_ID: #REF!
Name COL_CF_CF_INCOMES_CCY: #REF!

Sheet Samenvatting
C1: Private Equity and Private Debt Exposure
C2: John Huiberts
C3: ="Commitment of € " & TEXT(SUM(F43:F100), "#.##0,00") -> Commitment of € 51.268.000,00
L40: Projected
E41: Currency | F41: Commitment | G41: Deelnemingsvrijstelling | H41: IRR | I41: Close | K41: Instap Jaar | L41: 46387 | M41: =EOMONTH(L41,12) -> 46752 | N41: =EOMONTH(M41,12) -> 47118 | O41: =EOMONTH(N41,12) -> 47483 | P41: =EOMONTH(O41,12) -> 47848 | Q41: =EOMONTH(P41,12) -> 48213 | R41: =EOMONTH(Q41,12) -> 48579 | S41: =EOMONTH(R41,12) -> 48944 | T41: =EOMONTH(S41,12) -> 49309 | ... AU41: =EOMONTH(AT41,12) -> 59171
C42: Capital calls | D42: Fondstype | E42: currency | F42: bedrag
C43: Secondaries Dummy | D43: =_xlfn.XLOOKUP(C43,Fondsen!B:B,Fondsen!C:C,"0",0,1) -> Secondaries | E43: EUR | F43: 5400000 | G43: =IFERROR(IF(SUM(OFFSET(INDEX('Capital Call&Distributions data'!A:A,MATCH(D43,'Capital Call&Distributions data'!A:A,0)),-1,2,1,1000))=0,"✔",""),"") | H43: =IFERROR(IRR(L43:AD43),"") -> 0.13229301 | I43: 46023 | J43: =YEAR(K43)-YEAR(I43) -> 0 | K43: 46023 | L43: {=IFERROR(IF(L$41<$K43,0,$F43*_xlfn.XLOOKUP($D43,'Capital Call&Distributions data'!$A:$A,INDEX('Capital Call&Distributions data'!$C:$Q,0,MIN(MAX(YEAR(L$41)-YEAR($K43)+$J43+1,1),14)))),0)} -> -2874338.1 | M43: {=IFERROR(IF(M$41<$K43,0,$F43*_xlfn.XLOOKUP($D43,'Capital Call&Distributions data'!$A:$A,INDEX('Capital Call&Distributions data'!$C:$Q,0,MIN(MAX(YEAR(M$41)-YEAR($K43)+$J43+1,1),14)))),0)} -> -257661.94 | N43: {=IFERROR(IF(N$41<$K43,0,$F43*_xlfn.XLOOKUP($D43,'Capital Call&Distributions data'!$A:$A,INDEX('Capital Call&Distributions data'!$C:$Q,0,MIN(MAX(YEAR(N$41)-YEAR($K43)+$J43+1,1),14)))),0)} -> 1376644.4 | O43: {=IFERROR(IF(O$41<$K43,0,$F43*_xlfn.XLOOKUP($D43,'Capital Call&Distributions data'!$A:$A,INDEX('Capital Call&Distributions data'!$C:$Q,0,MIN(MAX(YEAR(O$41)-YEAR($K43)+$J43+1,1),14)))),0)} -> 1132342.3 | P43: {=IFERROR(IF(P$41<$K43,0,$F43*_xlfn.XLOOKUP($D43,'Capital Call&Distributions data'!$A:$A,INDEX('Capital Call&Distributions data'!$C:$Q,0,MIN(MAX(YEAR(P$41)-YEAR($K43)+$J43+1,1),14)))),0)} -> 785231.73 | Q43: {=IFERROR(IF(Q$41<$K43,0,$F43*_xlfn.XLOOKUP($D43,'Capital Call&Distributions data'!$A:$A,INDEX('Capital Call&Distributions data'!$C:$Q,0,MIN(MAX(YEAR(Q$41)-YEAR($K43)+$J43+1,1),14)))),0)} -> 442209.49 | R43: {=IFERROR(IF(R$41<$K43,0,$F43*_xlfn.XLOOKUP($D43,'Capital Call&Distributions data'!$A:$A,INDEX('Capital Call&Distributions data'!$C:$Q,0,MIN(MAX(YEAR(R$41)-YEAR($K43)+$J43+1,1),14)))),0)} -> 496557.37 | S43: {=IFERROR(IF(S$41<$K43,0,$F43*_xlfn.XLOOKUP($D43,'Capital Call&Distributions data'!$A:$A,INDEX('Capital Call&Distributions data'!$C:$Q,0,MIN(MAX(YEAR(S$41)-YEAR($K43)+$J43+1,1),14)))),0)} -> 410140.86 | T43: {=IFERROR(IF(T$41<$K43,0,$F43*_xlfn.XLOOKUP($D43,'Capital Call&Distributions data'!$A:$A,INDEX('Capital Call&Distributions data'!$C:$Q,0,MIN(MAX(YEAR(T$41)-YEAR($K43)+$J43+1,1),14)))),0)} -> 284566.87 | U43: {=IFERROR(IF(U$41<$K43,0,$F43*_xlfn.XLOOKUP($D43,'Capital Call&Distributions data'!$A:$A,INDEX('Capital Call&Distributions data'!$C:$O,0,MIN(MAX(YEAR(U$41)-YEAR($K43)+$J43+1,1),14)))),0)} -> 44220.949 | V43: {=IFERROR(IF(V$41<$K43,0,$F43*_xlfn.XLOOKUP($D43,'Capital Call&Distributions data'!$A:$A,INDEX('Capital Call&Distributions data'!$C:$O,0,MIN(MAX(YEAR(V$41)-YEAR($K43)+$J43+1,1),14)))),0)} -> 19241.176 | W43: {=IFERROR(IF(W$41<$K43,0,$F43*_xlfn.XLOOKUP($D43,'Capital Call&Distributions data'!$A:$A,INDEX('Capital Call&Distributions data'!$C:$O,0,MIN(MAX(YEAR(W$41)-YEAR($K43)+$J43+1,1),14)))),0)} -> 0 | X43: {=IFERROR(IF(X$41<$K43,0,$F43*_xlfn.XLOOKUP($D43,'Capital Call&Distributions data'!$A:$A,INDEX('Capital Call&Distributions data'!$C:$O,0,MIN(MAX(YEAR(X$41)-YEAR($K43)+$J43+1,1),14)))),0)} -> 0 | Y43: {=IFERROR(IF(Y$41<$K43,0,$F43*_xlfn.XLOOKUP($D43,'Capital Call&Distributions data'!$A:$A,INDEX('Capital Call&Distributions data'!$C:$O,0,MIN(MAX(YEAR(Y$41)-YEAR($K43)+$J43+1,1),14)))),0)} -> 0 | Z43: {=IFERROR(IF(Z$41<$K43,0,$F43*_xlfn.XLOOKUP($D43,'Capital Call&Distributions data'!$A:$A,INDEX('Capital Call&Distributions data'!$C:$O,0,MIN(MAX(YEAR(Z$41)-YEAR($K43)+$J43+1,1),14)))),0)} -> 0 | AA43: {=IFERROR(IF(AA$41<$K43,0,$F43*_xlfn.XLOOKUP($D43,'Capital Call&Distributions data'!$A:$A,INDEX('Capital Call&Distributions data'!$C:$O,0,MIN(MAX(YEAR(AA$41)-YEAR($K43)+$J43+1,1),14)))),0)} -> 0 | AB43: {=IFERROR(IF(AB$41<$K43,0,$F43*_xlfn.XLOOKUP($D43,'Capital Call&Distributions data'!$A:$A,INDEX('Capital Call&Distributions data'!$C:$O,0,MIN(MAX(YEAR(AB$41)-YEAR($K43)+$J43+1,1),14)))),0)} -> 0 | ... AU43: {=IFERROR(IF(AU$41<$K43,0,$F43*_xlfn.XLOOKUP($D43,'Capital Call&Distributions data'!$A:$A,INDEX('Capital Call&Distributions data'!$C:$O,0,MIN(MAX(YEAR(AU$41)-YEAR($K43)+$J43+1,1),14)))),0)} -> 0
C44: PE dummy | D44: =_xlfn.XLOOKUP(C44,Fondsen!B:B,Fondsen!C:C,"0",0,1) -> PE | E44: EUR | F44: 2500000 | G44: =IFERROR(IF(SUM(OFFSET(INDEX('Capital Call&Distributions data'!A:A,MATCH(D44,'Capital Call&Distributions data'!A:A,0)),-1,2,1,1000))=0,"✔",""),"") | H44: =IFERROR(IRR(L44:AD44),"") -> 0.1472451 | I44: 46023 | J44: =YEAR(K44)-YEAR(I44) -> 0 | K44: 46023 | L44: {=IFERROR(IF(L$41<$K44,0,$F44*_xlfn.XLOOKUP($D44,'Capital Call&Distributions data'!$A:$A,INDEX('Capital Call&Distributions data'!$C:$O,0,MIN(MAX(YEAR(L$41)-YEAR($K44)+$J44+1,1),14)))),0)} -> -786543.29 | M44: {=IFERROR(IF(M$41<$K44,0,$F44*_xlfn.XLOOKUP($D44,'Capital Call&Distributions data'!$A:$A,INDEX('Capital Call&Distributions data'!$C:$O,0,MIN(MAX(YEAR(M$41)-YEAR($K44)+$J44+1,1),14)))),0)} -> -546580.93 | N44: {=IFERROR(IF(N$41<$K44,0,$F44*_xlfn.XLOOKUP($D44,'Capital Call&Distributions data'!$A:$A,INDEX('Capital Call&Distributions data'!$C:$O,0,MIN(MAX(YEAR(N$41)-YEAR($K44)+$J44+1,1),14)))),0)} -> -546580.93 | O44: {=IFERROR(IF(O$41<$K44,0,$F44*_xlfn.XLOOKUP($D44,'Capital Call&Distributions data'!$A:$A,INDEX('Capital Call&Distributions data'!$C:$O,0,MIN(MAX(YEAR(O$41)-YEAR($K44)+$J44+1,1),14)))),0)} -> -245294.86 | P44: {=IFERROR(IF(P$41<$K44,0,$F44*_xlfn.XLOOKUP($D44,'Capital Call&Distributions data'!$A:$A,INDEX('Capital Call&Distributions data'!$C:$O,0,MIN(MAX(YEAR(P$41)-YEAR($K44)+$J44+1,1),14)))),0)} -> 633993.2 | Q44: {=IFERROR(IF(Q$41<$K44,0,$F44*_xlfn.XLOOKUP($D44,'Capital Call&Distributions data'!$A:$A,INDEX('Capital Call&Distributions data'!$C:$O,0,MIN(MAX(YEAR(Q$41)-YEAR($K44)+$J44+1,1),14)))),0)} -> 1046504.1 | R44: {=IFERROR(IF(R$41<$K44,0,$F44*_xlfn.XLOOKUP($D44,'Capital Call&Distributions data'!$A:$A,INDEX('Capital Call&Distributions data'!$C:$O,0,MIN(MAX(YEAR(R$41)-YEAR($K44)+$J44+1,1),14)))),0)} -> 1042664 | S44: {=IFERROR(IF(S$41<$K44,0,$F44*_xlfn.XLOOKUP($D44,'Capital Call&Distributions data'!$A:$A,INDEX('Capital Call&Distributions data'!$C:$O,0,MIN(MAX(YEAR(S$41)-YEAR($K44)+$J44+1,1),14)))),0)} -> 628564.66 | ... AU44: {=IFERROR(IF(AU$41<$K44,0,$F44*_xlfn.XLOOKUP($D44,'Capital Call&Distributions data'!$A:$A,INDEX('Capital Call&Distributions data'!$C:$O,0,MIN(MAX(YEAR(AU$41)-YEAR($K44)+$J44+1,1),14)))),0)} -> 0
C45: Secondaries Dummy | D45: =_xlfn.XLOOKUP(C45,Fondsen!B:B,Fondsen!C:C,"0",0,1) -> Secondaries | E45: EUR | F45: 5100000 | G45: =IFERROR(IF(SUM(OFFSET(INDEX('Capital Call&Distributions data'!A:A,MATCH(D45,'Capital Call&Distributions data'!A:A,0)),-1,2,1,1000))=0,"✔",""),"") | H45: =IFERROR(IRR(L45:AD45),"") -> 0.13229301 | I45: 46388 | J45: =YEAR(K45)-YEAR(I45) -> 0 | K45: 46388 | L45: {=IFERROR(IF(L$41<$K45,0,$F45*_xlfn.XLOOKUP($D45,'Capital Call&Distributions data'!$A:$A,INDEX('Capital Call&Distributions data'!$C:$O,0,MIN(MAX(YEAR(L$41)-YEAR($K45)+$J45+1,1),14)))),0)} -> 0 | M45: {=IFERROR(IF(M$41<$K45,0,$F45*_xlfn.XLOOKUP($D45,'Capital Call&Distributions data'!$A:$A,INDEX('Capital Call&Distributions data'!$C:$O,0,MIN(MAX(YEAR(M$41)-YEAR($K45)+$J45+1,1),14)))),0)} -> -2714652.6 | N45: {=IFERROR(IF(N$41<$K45,0,$F45*_xlfn.XLOOKUP($D45,'Capital Call&Distributions data'!$A:$A,INDEX('Capital Call&Distributions data'!$C:$O,0,MIN(MAX(YEAR(N$41)-YEAR($K45)+$J45+1,1),14)))),0)} -> -243347.39 | O45: {=IFERROR(IF(O$41<$K45,0,$F45*_xlfn.XLOOKUP($D45,'Capital Call&Distributions data'!$A:$A,INDEX('Capital Call&Distributions data'!$C:$O,0,MIN(MAX(YEAR(O$41)-YEAR($K45)+$J45+1,1),14)))),0)} -> 1300164.2 | P45: {=IFERROR(IF(P$41<$K45,0,$F45*_xlfn.XLOOKUP($D45,'Capital Call&Distributions data'!$A:$A,INDEX('Capital Call&Distributions data'!$C:$O,0,MIN(MAX(YEAR(P$41)-YEAR($K45)+$J45+1,1),14)))),0)} -> 1069434.4 | Q45: {=IFERROR(IF(Q$41<$K45,0,$F45*_xlfn.XLOOKUP($D45,'Capital Call&Distributions data'!$A:$A,INDEX('Capital Call&Distributions data'!$C:$O,0,MIN(MAX(YEAR(Q$41)-YEAR($K45)+$J45+1,1),14)))),0)} -> 741607.74 | R45: {=IFERROR(IF(R$41<$K45,0,$F45*_xlfn.XLOOKUP($D45,'Capital Call&Distributions data'!$A:$A,INDEX('Capital Call&Distributions data'!$C:$O,0,MIN(MAX(YEAR(R$41)-YEAR($K45)+$J45+1,1),14)))),0)} -> 417642.29 | S45: {=IFERROR(IF(S$41<$K45,0,$F45*_xlfn.XLOOKUP($D45,'Capital Call&Distributions data'!$A:$A,INDEX('Capital Call&Distributions data'!$C:$O,0,MIN(MAX(YEAR(S$41)-YEAR($K45)+$J45+1,1),14)))),0)} -> 468970.85 | ... AU45: {=IFERROR(IF(AU$41<$K45,0,$F45*_xlfn.XLOOKUP($D45,'Capital Call&Distributions data'!$A:$A,INDEX('Capital Call&Distributions data'!$C:$O,0,MIN(MAX(YEAR(AU$41)-YEAR($K45)+$J45+1,1),14)))),0)} -> 0
C46: PE dummy | D46: =_xlfn.XLOOKUP(C46,Fondsen!B:B,Fondsen!C:C,"0",0,1) -> PE | E46: EUR | F46: 2020000 | G46: =IFERROR(IF(SUM(OFFSET(INDEX('Capital Call&Distributions data'!A:A,MATCH(D46,'Capital Call&Distributions data'!A:A,0)),-1,2,1,1000))=0,"✔",""),"") | H46: =IFERROR(IRR(L46:AD46),"") -> 0.1472451 | I46: 46388 | J46: =YEAR(K46)-YEAR(I46) -> 0 | K46: 46388 | L46: {=IFERROR(IF(L$41<$K46,0,$F46*_xlfn.XLOOKUP($D46,'Capital Call&Distributions data'!$A:$A,INDEX('Capital Call&Distributions data'!$C:$O,0,MIN(MAX(YEAR(L$41)-YEAR($K46)+$J46+1,1),14)))),0)} -> 0 | M46: {=IFERROR(IF(M$41<$K46,0,$F46*_xlfn.XLOOKUP($D46,'Capital Call&Distributions data'!$A:$A,INDEX('Capital Call&Distributions data'!$C:$O,0,MIN(MAX(YEAR(M$41)-YEAR($K46)+$J46+1,1),14)))),0)} -> -635526.98 | N46: {=IFERROR(IF(N$41<$K46,0,$F46*_xlfn.XLOOKUP($D46,'Capital Call&Distributions data'!$A:$A,INDEX('Capital Call&Distributions data'!$C:$O,0,MIN(MAX(YEAR(N$41)-YEAR($K46)+$J46+1,1),14)))),0)} -> -441637.39 | O46: {=IFERROR(IF(O$41<$K46,0,$F46*_xlfn.XLOOKUP($D46,'Capital Call&Distributions data'!$A:$A,INDEX('Capital Call&Distributions data'!$C:$O,0,MIN(MAX(YEAR(O$41)-YEAR($K46)+$J46+1,1),14)))),0)} -> -441637.39 | P46: {=IFERROR(IF(P$41<$K46,0,$F46*_xlfn.XLOOKUP($D46,'Capital Call&Distributions data'!$A:$A,INDEX('Capital Call&Distributions data'!$C:$O,0,MIN(MAX(YEAR(P$41)-YEAR($K46)+$J46+1,1),14)))),0)} -> -198198.24 | Q46: {=IFERROR(IF(Q$41<$K46,0,$F46*_xlfn.XLOOKUP($D46,'Capital Call&Distributions data'!$A:$A,INDEX('Capital Call&Distributions data'!$C:$O,0,MIN(MAX(YEAR(Q$41)-YEAR($K46)+$J46+1,1),14)))),0)} -> 512266.5 | R46: {=IFERROR(IF(R$41<$K46,0,$F46*_xlfn.XLOOKUP($D46,'Capital Call&Distributions data'!$A:$A,INDEX('Capital Call&Distributions data'!$C:$O,0,MIN(MAX(YEAR(R$41)-YEAR($K46)+$J46+1,1),14)))),0)} -> 845575.28 | S46: {=IFERROR(IF(S$41<$K46,0,$F46*_xlfn.XLOOKUP($D46,'Capital Call&Distributions data'!$A:$A,INDEX('Capital Call&Distributions data'!$C:$O,0,MIN(MAX(YEAR(S$41)-YEAR($K46)+$J46+1,1),14)))),0)} -> 842472.5 | ... AU46: {=IFERROR(IF(AU$41<$K46,0,$F46*_xlfn.XLOOKUP($D46,'Capital Call&Distributions data'!$A:$A,INDEX('Capital Call&Distributions data'!$C:$O,0,MIN(MAX(YEAR(AU$41)-YEAR($K46)+$J46+1,1),14)))),0)} -> 0
C47: Secondaries Dummy | D47: =_xlfn.XLOOKUP(C47,Fondsen!B:B,Fondsen!C:C,"0",0,1) -> Secondaries | E47: EUR | F47: 3200000 | G47: =IFERROR(IF(SUM(OFFSET(INDEX('Capital Call&Distributions data'!A:A,MATCH(D47,'Capital Call&Distributions data'!A:A,0)),-1,2,1,1000))=0,"✔",""),"") | H47: =IFERROR(IRR(L47:AD47),"") -> 0.13229301 | I47: 46753 | J47: =YEAR(K47)-YEAR(I47) -> 0 | K47: 46753 | L47: {=IFERROR(IF(L$41<$K47,0,$F47*_xlfn.XLOOKUP($D47,'Capital Call&Distributions data'!$A:$A,INDEX('Capital Call&Distributions data'!$C:$O,0,MIN(MAX(YEAR(L$41)-YEAR($K47)+$J47+1,1),14)))),0)} -> 0 | M47: {=IFERROR(IF(M$41<$K47,0,$F47*_xlfn.XLOOKUP($D47,'Capital Call&Distributions data'!$A:$A,INDEX('Capital Call&Distributions data'!$C:$O,0,MIN(MAX(YEAR(M$41)-YEAR($K47)+$J47+1,1),14)))),0)} -> 0 | N47: {=IFERROR(IF(N$41<$K47,0,$F47*_xlfn.XLOOKUP($D47,'Capital Call&Distributions data'!$A:$A,INDEX('Capital Call&Distributions data'!$C:$O,0,MIN(MAX(YEAR(N$41)-YEAR($K47)+$J47+1,1),14)))),0)} -> -1703311.4 | O47: {=IFERROR(IF(O$41<$K47,0,$F47*_xlfn.XLOOKUP($D47,'Capital Call&Distributions data'!$A:$A,INDEX('Capital Call&Distributions data'!$C:$O,0,MIN(MAX(YEAR(O$41)-YEAR($K47)+$J47+1,1),14)))),0)} -> -152688.56 | P47: {=IFERROR(IF(P$41<$K47,0,$F47*_xlfn.XLOOKUP($D47,'Capital Call&Distributions data'!$A:$A,INDEX('Capital Call&Distributions data'!$C:$O,0,MIN(MAX(YEAR(P$41)-YEAR($K47)+$J47+1,1),14)))),0)} -> 815789.28 | Q47: {=IFERROR(IF(Q$41<$K47,0,$F47*_xlfn.XLOOKUP($D47,'Capital Call&Distributions data'!$A:$A,INDEX('Capital Call&Distributions data'!$C:$O,0,MIN(MAX(YEAR(Q$41)-YEAR($K47)+$J47+1,1),14)))),0)} -> 671017.69 | R47: {=IFERROR(IF(R$41<$K47,0,$F47*_xlfn.XLOOKUP($D47,'Capital Call&Distributions data'!$A:$A,INDEX('Capital Call&Distributions data'!$C:$O,0,MIN(MAX(YEAR(R$41)-YEAR($K47)+$J47+1,1),14)))),0)} -> 465322.5 | S47: {=IFERROR(IF(S$41<$K47,0,$F47*_xlfn.XLOOKUP($D47,'Capital Call&Distributions data'!$A:$A,INDEX('Capital Call&Distributions data'!$C:$O,0,MIN(MAX(YEAR(S$41)-YEAR($K47)+$J47+1,1),14)))),0)} -> 262050.07 | ... AU47: {=IFERROR(IF(AU$41<$K47,0,$F47*_xlfn.XLOOKUP($D47,'Capital Call&Distributions data'!$A:$A,INDEX('Capital Call&Distributions data'!$C:$O,0,MIN(MAX(YEAR(AU$41)-YEAR($K47)+$J47+1,1),14)))),0)} -> 0
C48: PE dummy | D48: =_xlfn.XLOOKUP(C48,Fondsen!B:B,Fondsen!C:C,"0",0,1) -> PE | E48: EUR | F48: 2000000 | G48: =IFERROR(IF(SUM(OFFSET(INDEX('Capital Call&Distributions data'!A:A,MATCH(D48,'Capital Call&Distributions data'!A:A,0)),-1,2,1,1000))=0,"✔",""),"") | H48: =IFERROR(IRR(L48:AJ48),"") -> 0.1472451 | I48: 46753 | J48: =YEAR(K48)-YEAR(I48) -> 0 | K48: 46753 | L48: {=IFERROR(IF(L$41<$K48,0,$F48*_xlfn.XLOOKUP($D48,'Capital Call&Distributions data'!$A:$A,INDEX('Capital Call&Distributions data'!$C:$O,0,MIN(MAX(YEAR(L$41)-YEAR($K48)+$J48+1,1),14)))),0)} -> 0 | M48: {=IFERROR(IF(M$41<$K48,0,$F48*_xlfn.XLOOKUP($D48,'Capital Call&Distributions data'!$A:$A,INDEX('Capital Call&Distributions data'!$C:$O,0,MIN(MAX(YEAR(M$41)-YEAR($K48)+$J48+1,1),14)))),0)} -> 0 | N48: {=IFERROR(IF(N$41<$K48,0,$F48*_xlfn.XLOOKUP($D48,'Capital Call&Distributions data'!$A:$A,INDEX('Capital Call&Distributions data'!$C:$O,0,MIN(MAX(YEAR(N$41)-YEAR($K48)+$J48+1,1),14)))),0)} -> -629234.63 | O48: {=IFERROR(IF(O$41<$K48,0,$F48*_xlfn.XLOOKUP($D48,'Capital Call&Distributions data'!$A:$A,INDEX('Capital Call&Distributions data'!$C:$O,0,MIN(MAX(YEAR(O$41)-YEAR($K48)+$J48+1,1),14)))),0)} -> -437264.74 | P48: {=IFERROR(IF(P$41<$K48,0,$F48*_xlfn.XLOOKUP($D48,'Capital Call&Distributions data'!$A:$A,INDEX('Capital Call&Distributions data'!$C:$O,0,MIN(MAX(YEAR(P$41)-YEAR($K48)+$J48+1,1),14)))),0)} -> -437264.74 | Q48: {=IFERROR(IF(Q$41<$K48,0,$F48*_xlfn.XLOOKUP($D48,'Capital Call&Distributions data'!$A:$A,INDEX('Capital Call&Distributions data'!$C:$O,0,MIN(MAX(YEAR(Q$41)-YEAR($K48)+$J48+1,1),14)))),0)} -> -196235.88 | R48: {=IFERROR(IF(R$41<$K48,0,$F48*_xlfn.XLOOKUP($D48,'Capital Call&Distributions data'!$A:$A,INDEX('Capital Call&Distributions data'!$C:$O,0,MIN(MAX(YEAR(R$41)-YEAR($K48)+$J48+1,1),14)))),0)} -> 507194.56 | S48: {=IFERROR(IF(S$41<$K48,0,$F48*_xlfn.XLOOKUP($D48,'Capital Call&Distributions data'!$A:$A,INDEX('Capital Call&Distributions data'!$C:$O,0,MIN(MAX(YEAR(S$41)-YEAR($K48)+$J48+1,1),14)))),0)} -> 837203.24 | ... AU48: {=IFERROR(IF(AU$41<$K48,0,$F48*_xlfn.XLOOKUP($D48,'Capital Call&Distributions data'!$A:$A,INDEX('Capital Call&Distributions data'!$C:$O,0,MIN(MAX(YEAR(AU$41)-YEAR($K48)+$J48+1,1),14)))),0)} -> 0
C49: Secondaries Dummy | D49: =_xlfn.XLOOKUP(C49,Fondsen!B:B,Fondsen!C:C,"0",0,1) -> Secondaries | E49: EUR | F49: 1580000 | G49: =IFERROR(IF(SUM(OFFSET(INDEX('Capital Call&Distributions data'!A:A,MATCH(D49,'Capital Call&Distributions data'!A:A,0)),-1,2,1,1000))=0,"✔",""),"") | H49: =IFERROR(IRR(L49:AK49),"") -> 0.13229301 | I49: 47119 | J49: =YEAR(K49)-YEAR(I49) -> 0 | K49: 47119 | L49: {=IFERROR(IF(L$41<$K49,0,$F49*_xlfn.XLOOKUP($D49,'Capital Call&Distributions data'!$A:$A,INDEX('Capital Call&Distributions data'!$C:$O,0,MIN(MAX(YEAR(L$41)-YEAR($K49)+$J49+1,1),14)))),0)} -> 0 | M49: {=IFERROR(IF(M$41<$K49,0,$F49*_xlfn.XLOOKUP($D49,'Capital Call&Distributions data'!$A:$A,INDEX('Capital Call&Distributions data'!$C:$O,0,MIN(MAX(YEAR(M$41)-YEAR($K49)+$J49+1,1),14)))),0)} -> 0 | N49: {=IFERROR(IF(N$41<$K49,0,$F49*_xlfn.XLOOKUP($D49,'Capital Call&Distributions data'!$A:$A,INDEX('Capital Call&Distributions data'!$C:$O,0,MIN(MAX(YEAR(N$41)-YEAR($K49)+$J49+1,1),14)))),0)} -> 0 | O49: {=IFERROR(IF(O$41<$K49,0,$F49*_xlfn.XLOOKUP($D49,'Capital Call&Distributions data'!$A:$A,INDEX('Capital Call&Distributions data'!$C:$O,0,MIN(MAX(YEAR(O$41)-YEAR($K49)+$J49+1,1),14)))),0)} -> -841010.02 | P49: {=IFERROR(IF(P$41<$K49,0,$F49*_xlfn.XLOOKUP($D49,'Capital Call&Distributions data'!$A:$A,INDEX('Capital Call&Distributions data'!$C:$O,0,MIN(MAX(YEAR(P$41)-YEAR($K49)+$J49+1,1),14)))),0)} -> -75389.976 | Q49: {=IFERROR(IF(Q$41<$K49,0,$F49*_xlfn.XLOOKUP($D49,'Capital Call&Distributions data'!$A:$A,INDEX('Capital Call&Distributions data'!$C:$O,0,MIN(MAX(YEAR(Q$41)-YEAR($K49)+$J49+1,1),14)))),0)} -> 402795.96 | R49: {=IFERROR(IF(R$41<$K49,0,$F49*_xlfn.XLOOKUP($D49,'Capital Call&Distributions data'!$A:$A,INDEX('Capital Call&Distributions data'!$C:$O,0,MIN(MAX(YEAR(R$41)-YEAR($K49)+$J49+1,1),14)))),0)} -> 331314.98 | S49: {=IFERROR(IF(S$41<$K49,0,$F49*_xlfn.XLOOKUP($D49,'Capital Call&Distributions data'!$A:$A,INDEX('Capital Call&Distributions data'!$C:$O,0,MIN(MAX(YEAR(S$41)-YEAR($K49)+$J49+1,1),14)))),0)} -> 229752.99 | ... AU49: {=IFERROR(IF(AU$41<$K49,0,$F49*_xlfn.XLOOKUP($D49,'Capital Call&Distributions data'!$A:$A,INDEX('Capital Call&Distributions data'!$C:$O,0,MIN(MAX(YEAR(AU$41)-YEAR($K49)+$J49+1,1),14)))),0)} -> 0
C50: PE dummy | D50: =_xlfn.XLOOKUP(C50,Fondsen!B:B,Fondsen!C:C,"0",0,1) -> PE | E50: EUR | F50: 1000000 | G50: =IFERROR(IF(SUM(OFFSET(INDEX('Capital Call&Distributions data'!A:A,MATCH(D50,'Capital Call&Distributions data'!A:A,0)),-1,2,1,1000))=0,"✔",""),"") | H50: =IFERROR(IRR(L50:AL50),"") -> 0.1472451 | I50: 47119 | J50: =YEAR(K50)-YEAR(I50) -> 0 | K50: 47119 | L50: {=IFERROR(IF(L$41<$K50,0,$F50*_xlfn.XLOOKUP($D50,'Capital Call&Distributions data'!$A:$A,INDEX('Capital Call&Distributions data'!$C:$O,0,MIN(MAX(YEAR(L$41)-YEAR($K50)+$J50+1,1),14)))),0)} -> 0 | M50: {=IFERROR(IF(M$41<$K50,0,$F50*_xlfn.XLOOKUP($D50,'Capital Call&Distributions data'!$A:$A,INDEX('Capital Call&Distributions data'!$C:$O,0,MIN(MAX(YEAR(M$41)-YEAR($K50)+$J50+1,1),14)))),0)} -> 0 | N50: {=IFERROR(IF(N$41<$K50,0,$F50*_xlfn.XLOOKUP($D50,'Capital Call&Distributions data'!$A:$A,INDEX('Capital Call&Distributions data'!$C:$O,0,MIN(MAX(YEAR(N$41)-YEAR($K50)+$J50+1,1),14)))),0)} -> 0 | O50: {=IFERROR(IF(O$41<$K50,0,$F50*_xlfn.XLOOKUP($D50,'Capital Call&Distributions data'!$A:$A,INDEX('Capital Call&Distributions data'!$C:$O,0,MIN(MAX(YEAR(O$41)-YEAR($K50)+$J50+1,1),14)))),0)} -> -314617.31 | P50: {=IFERROR(IF(P$41<$K50,0,$F50*_xlfn.XLOOKUP($D50,'Capital Call&Distributions data'!$A:$A,INDEX('Capital Call&Distributions data'!$C:$O,0,MIN(MAX(YEAR(P$41)-YEAR($K50)+$J50+1,1),14)))),0)} -> -218632.37 | Q50: {=IFERROR(IF(Q$41<$K50,0,$F50*_xlfn.XLOOKUP($D50,'Capital Call&Distributions data'!$A:$A,INDEX('Capital Call&Distributions data'!$C:$O,0,MIN(MAX(YEAR(Q$41)-YEAR($K50)+$J50+1,1),14)))),0)} -> -218632.37 | R50: {=IFERROR(IF(R$41<$K50,0,$F50*_xlfn.XLOOKUP($D50,'Capital Call&Distributions data'!$A:$A,INDEX('Capital Call&Distributions data'!$C:$O,0,MIN(MAX(YEAR(R$41)-YEAR($K50)+$J50+1,1),14)))),0)} -> -98117.942 | S50: {=IFERROR(IF(S$41<$K50,0,$F50*_xlfn.XLOOKUP($D50,'Capital Call&Distributions data'!$A:$A,INDEX('Capital Call&Distributions data'!$C:$O,0,MIN(MAX(YEAR(S$41)-YEAR($K50)+$J50+1,1),14)))),0)} -> 253597.28 | ... AU50: {=IFERROR(IF(AU$41<$K50,0,$F50*_xlfn.XLOOKUP($D50,'Capital Call&Distributions data'!$A:$A,INDEX('Capital Call&Distributions data'!$C:$O,0,MIN(MAX(YEAR(AU$41)-YEAR($K50)+$J50+1,1),14)))),0)} -> 0
C51: Secondaries Dummy | D51: =_xlfn.XLOOKUP(C51,Fondsen!B:B,Fondsen!C:C,"0",0,1) -> Secondaries | E51: EUR | F51: 3280000 | G51: =IFERROR(IF(SUM(OFFSET(INDEX('Capital Call&Distributions data'!A:A,MATCH(D51,'Capital Call&Distributions data'!A:A,0)),-1,2,1,1000))=0,"✔",""),"") | H51: =IFERROR(IRR(L51:AD51),"") -> 0.13229301 | I51: 47484 | J51: =YEAR(K51)-YEAR(I51) -> 0 | K51: 47484 | L51: {=IFERROR(IF(L$41<$K51,0,$F51*_xlfn.XLOOKUP($D51,'Capital Call&Distributions data'!$A:$A,INDEX('Capital Call&Distributions data'!$C:$O,0,MIN(MAX(YEAR(L$41)-YEAR($K51)+$J51+1,1),14)))),0)} -> 0 | M51: {=IFERROR(IF(M$41<$K51,0,$F51*_xlfn.XLOOKUP($D51,'Capital Call&Distributions data'!$A:$A,INDEX('Capital Call&Distributions data'!$C:$O,0,MIN(MAX(YEAR(M$41)-YEAR($K51)+$J51+1,1),14)))),0)} -> 0 | N51: {=IFERROR(IF(N$41<$K51,0,$F51*_xlfn.XLOOKUP($D51,'Capital Call&Distributions data'!$A:$A,INDEX('Capital Call&Distributions data'!$C:$O,0,MIN(MAX(YEAR(N$41)-YEAR($K51)+$J51+1,1),14)))),0)} -> 0 | O51: {=IFERROR(IF(O$41<$K51,0,$F51*_xlfn.XLOOKUP($D51,'Capital Call&Distributions data'!$A:$A,INDEX('Capital Call&Distributions data'!$C:$O,0,MIN(MAX(YEAR(O$41)-YEAR($K51)+$J51+1,1),14)))),0)} -> 0 | P51: {=IFERROR(IF(P$41<$K51,0,$F51*_xlfn.XLOOKUP($D51,'Capital Call&Distributions data'!$A:$A,INDEX('Capital Call&Distributions data'!$C:$O,0,MIN(MAX(YEAR(P$41)-YEAR($K51)+$J51+1,1),14)))),0)} -> -1745894.2 | Q51: {=IFERROR(IF(Q$41<$K51,0,$F51*_xlfn.XLOOKUP($D51,'Capital Call&Distributions data'!$A:$A,INDEX('Capital Call&Distributions data'!$C:$O,0,MIN(MAX(YEAR(Q$41)-YEAR($K51)+$J51+1,1),14)))),0)} -> -156505.77 | R51: {=IFERROR(IF(R$41<$K51,0,$F51*_xlfn.XLOOKUP($D51,'Capital Call&Distributions data'!$A:$A,INDEX('Capital Call&Distributions data'!$C:$O,0,MIN(MAX(YEAR(R$41)-YEAR($K51)+$J51+1,1),14)))),0)} -> 836184.02 | S51: {=IFERROR(IF(S$41<$K51,0,$F51*_xlfn.XLOOKUP($D51,'Capital Call&Distributions data'!$A:$A,INDEX('Capital Call&Distributions data'!$C:$O,0,MIN(MAX(YEAR(S$41)-YEAR($K51)+$J51+1,1),14)))),0)} -> 687793.13 | ... AU51: {=IFERROR(IF(AU$41<$K51,0,$F51*_xlfn.XLOOKUP($D51,'Capital Call&Distributions data'!$A:$A,INDEX('Capital Call&Distributions data'!$C:$O,0,MIN(MAX(YEAR(AU$41)-YEAR($K51)+$J51+1,1),14)))),0)} -> 0
C52: PE dummy | D52: =_xlfn.XLOOKUP(C52,Fondsen!B:B,Fondsen!C:C,"0",0,1) -> PE | E52: EUR | F52: 2000000 | G52: =IFERROR(IF(SUM(OFFSET(INDEX('Capital Call&Distributions data'!A:A,MATCH(D52,'Capital Call&Distributions data'!A:A,0)),-1,2,1,1000))=0,"✔",""),"") | H52: =IFERROR(IRR(L52:AD52),"") -> 0.1472451 | I52: 47484 | J52: =YEAR(K52)-YEAR(I52) -> 0 | K52: 47484 | L52: {=IFERROR(IF(L$41<$K52,0,$F52*_xlfn.XLOOKUP($D52,'Capital Call&Distributions data'!$A:$A,INDEX('Capital Call&Distributions data'!$C:$O,0,MIN(MAX(YEAR(L$41)-YEAR($K52)+$J52+1,1),14)))),0)} -> 0 | M52: {=IFERROR(IF(M$41<$K52,0,$F52*_xlfn.XLOOKUP($D52,'Capital Call&Distributions data'!$A:$A,INDEX('Capital Call&Distributions data'!$C:$O,0,MIN(MAX(YEAR(M$41)-YEAR($K52)+$J52+1,1),14)))),0)} -> 0 | N52: {=IFERROR(IF(N$41<$K52,0,$F52*_xlfn.XLOOKUP($D52,'Capital Call&Distributions data'!$A:$A,INDEX('Capital Call&Distributions data'!$C:$O,0,MIN(MAX(YEAR(N$41)-YEAR($K52)+$J52+1,1),14)))),0)} -> 0 | O52: {=IFERROR(IF(O$41<$K52,0,$F52*_xlfn.XLOOKUP($D52,'Capital Call&Distributions data'!$A:$A,INDEX('Capital Call&Distributions data'!$C:$O,0,MIN(MAX(YEAR(O$41)-YEAR($K52)+$J52+1,1),14)))),0)} -> 0 | P52: {=IFERROR(IF(P$41<$K52,0,$F52*_xlfn.XLOOKUP($D52,'Capital Call&Distributions data'!$A:$A,INDEX('Capital Call&Distributions data'!$C:$O,0,MIN(MAX(YEAR(P$41)-YEAR($K52)+$J52+1,1),14)))),0)} -> -629234.63 | Q52: {=IFERROR(IF(Q$41<$K52,0,$F52*_xlfn.XLOOKUP($D52,'Capital Call&Distributions data'!$A:$A,INDEX('Capital Call&Distributions data'!$C:$O,0,MIN(MAX(YEAR(Q$41)-YEAR($K52)+$J52+1,1),14)))),0)} -> -437264.74 | R52: {=IFERROR(IF(R$41<$K52,0,$F52*_xlfn.XLOOKUP($D52,'Capital Call&Distributions data'!$A:$A,INDEX('Capital Call&Distributions data'!$C:$O,0,MIN(MAX(YEAR(R$41)-YEAR($K52)+$J52+1,1),14)))),0)} -> -437264.74 | S52: {=IFERROR(IF(S$41<$K52,0,$F52*_xlfn.XLOOKUP($D52,'Capital Call&Distributions data'!$A:$A,INDEX('Capital Call&Distributions data'!$C:$O,0,MIN(MAX(YEAR(S$41)-YEAR($K52)+$J52+1,1),14)))),0)} -> -196235.88 | ... AU52: {=IFERROR(IF(AU$41<$K52,0,$F52*_xlfn.XLOOKUP($D52,'Capital Call&Distributions data'!$A:$A,INDEX('Capital Call&Distributions data'!$C:$O,0,MIN(MAX(YEAR(AU$41)-YEAR($K52)+$J52+1,1),14)))),0)} -> 0
C53: Secondaries Dummy | D53: =_xlfn.XLOOKUP(C53,Fondsen!B:B,Fondsen!C:C,"0",0,1) -> Secondaries | E53: EUR | F53: 4000000 | G53: =IFERROR(IF(SUM(OFFSET(INDEX('Capital Call&Distributions data'!A:A,MATCH(D53,'Capital Call&Distributions data'!A:A,0)),-1,2,1,1000))=0,"✔",""),"") | H53: =IFERROR(IRR(L53:AD53),"") -> 0.13229301 | I53: 47849 | J53: =YEAR(K53)-YEAR(I53) -> 0 | K53: 47849 | L53: {=IFERROR(IF(L$41<$K53,0,$F53*_xlfn.XLOOKUP($D53,'Capital Call&Distributions data'!$A:$A,INDEX('Capital Call&Distributions data'!$C:$O,0,MIN(MAX(YEAR(L$41)-YEAR($K53)+$J53+1,1),14)))),0)} -> 0 | M53: {=IFERROR(IF(M$41<$K53,0,$F53*_xlfn.XLOOKUP($D53,'Capital Call&Distributions data'!$A:$A,INDEX('Capital Call&Distributions data'!$C:$O,0,MIN(MAX(YEAR(M$41)-YEAR($K53)+$J53+1,1),14)))),0)} -> 0 | N53: {=IFERROR(IF(N$41<$K53,0,$F53*_xlfn.XLOOKUP($D53,'Capital Call&Distributions data'!$A:$A,INDEX('Capital Call&Distributions data'!$C:$O,0,MIN(MAX(YEAR(N$41)-YEAR($K53)+$J53+1,1),14)))),0)} -> 0 | O53: {=IFERROR(IF(O$41<$K53,0,$F53*_xlfn.XLOOKUP($D53,'Capital Call&Distributions data'!$A:$A,INDEX('Capital Call&Distributions data'!$C:$O,0,MIN(MAX(YEAR(O$41)-YEAR($K53)+$J53+1,1),14)))),0)} -> 0 | P53: {=IFERROR(IF(P$41<$K53,0,$F53*_xlfn.XLOOKUP($D53,'Capital Call&Distributions data'!$A:$A,INDEX('Capital Call&Distributions data'!$C:$O,0,MIN(MAX(YEAR(P$41)-YEAR($K53)+$J53+1,1),14)))),0)} -> 0 | Q53: {=IFERROR(IF(Q$41<$K53,0,$F53*_xlfn.XLOOKUP($D53,'Capital Call&Distributions data'!$A:$A,INDEX('Capital Call&Distributions data'!$C:$O,0,MIN(MAX(YEAR(Q$41)-YEAR($K53)+$J53+1,1),14)))),0)} -> -2129139.3 | R53: {=IFERROR(IF(R$41<$K53,0,$F53*_xlfn.XLOOKUP($D53,'Capital Call&Distributions data'!$A:$A,INDEX('Capital Call&Distributions data'!$C:$O,0,MIN(MAX(YEAR(R$41)-YEAR($K53)+$J53+1,1),14)))),0)} -> -190860.7 | S53: {=IFERROR(IF(S$41<$K53,0,$F53*_xlfn.XLOOKUP($D53,'Capital Call&Distributions data'!$A:$A,INDEX('Capital Call&Distributions data'!$C:$O,0,MIN(MAX(YEAR(S$41)-YEAR($K53)+$J53+1,1),14)))),0)} -> 1019736.6 | ... AU53: {=IFERROR(IF(AU$41<$K53,0,$F53*_xlfn.XLOOKUP($D53,'Capital Call&Distributions data'!$A:$A,INDEX('Capital Call&Distributions data'!$C:$O,0,MIN(MAX(YEAR(AU$41)-YEAR($K53)+$J53+1,1),14)))),0)} -> 0
C54: PE dummy | D54: =_xlfn.XLOOKUP(C54,Fondsen!B:B,Fondsen!C:C,"0",0,1) -> PE | E54: EUR | F54: 2150000 | G54: =IFERROR(IF(SUM(OFFSET(INDEX('Capital Call&Distributions data'!A:A,MATCH(D54,'Capital Call&Distributions data'!A:A,0)),-1,2,1,1000))=0,"✔",""),"") | H54: =IFERROR(IRR(L54:AD54),"") -> 0.1472451 | I54: 47849 | J54: =YEAR(K54)-YEAR(I54) -> 0 | K54: 47849 | L54: {=IFERROR(IF(L$41<$K54,0,$F54*_xlfn.XLOOKUP($D54,'Capital Call&Distributions data'!$A:$A,INDEX('Capital Call&Distributions data'!$C:$O,0,MIN(MAX(YEAR(L$41)-YEAR($K54)+$J54+1,1),14)))),0)} -> 0 | M54: {=IFERROR(IF(M$41<$K54,0,$F54*_xlfn.XLOOKUP($D54,'Capital Call&Distributions data'!$A:$A,INDEX('Capital Call&Distributions data'!$C:$O,0,MIN(MAX(YEAR(M$41)-YEAR($K54)+$J54+1,1),14)))),0)} -> 0 | N54: {=IFERROR(IF(N$41<$K54,0,$F54*_xlfn.XLOOKUP($D54,'Capital Call&Distributions data'!$A:$A,INDEX('Capital Call&Distributions data'!$C:$O,0,MIN(MAX(YEAR(N$41)-YEAR($K54)+$J54+1,1),14)))),0)} -> 0 | O54: {=IFERROR(IF(O$41<$K54,0,$F54*_xlfn.XLOOKUP($D54,'Capital Call&Distributions data'!$A:$A,INDEX('Capital Call&Distributions data'!$C:$O,0,MIN(MAX(YEAR(O$41)-YEAR($K54)+$J54+1,1),14)))),0)} -> 0 | P54: {=IFERROR(IF(P$41<$K54,0,$F54*_xlfn.XLOOKUP($D54,'Capital Call&Distributions data'!$A:$A,INDEX('Capital Call&Distributions data'!$C:$O,0,MIN(MAX(YEAR(P$41)-YEAR($K54)+$J54+1,1),14)))),0)} -> 0 | Q54: {=IFERROR(IF(Q$41<$K54,0,$F54*_xlfn.XLOOKUP($D54,'Capital Call&Distributions data'!$A:$A,INDEX('Capital Call&Distributions data'!$C:$O,0,MIN(MAX(YEAR(Q$41)-YEAR($K54)+$J54+1,1),14)))),0)} -> -676427.23 | R54: {=IFERROR(IF(R$41<$K54,0,$F54*_xlfn.XLOOKUP($D54,'Capital Call&Distributions data'!$A:$A,INDEX('Capital Call&Distributions data'!$C:$O,0,MIN(MAX(YEAR(R$41)-YEAR($K54)+$J54+1,1),14)))),0)} -> -470059.6 | S54: {=IFERROR(IF(S$41<$K54,0,$F54*_xlfn.XLOOKUP($D54,'Capital Call&Distributions data'!$A:$A,INDEX('Capital Call&Distributions data'!$C:$O,0,MIN(MAX(YEAR(S$41)-YEAR($K54)+$J54+1,1),14)))),0)} -> -470059.6 | ... AU54: {=IFERROR(IF(AU$41<$K54,0,$F54*_xlfn.XLOOKUP($D54,'Capital Call&Distributions data'!$A:$A,INDEX('Capital Call&Distributions data'!$C:$O,0,MIN(MAX(YEAR(AU$41)-YEAR($K54)+$J54+1,1),14)))),0)} -> 0
C55: Secondaries Dummy | D55: =_xlfn.XLOOKUP(C55,Fondsen!B:B,Fondsen!C:C,"0",0,1) -> Secondaries | E55: EUR | F55: 5265000 | G55: =IFERROR(IF(SUM(OFFSET(INDEX('Capital Call&Distributions data'!A:A,MATCH(D55,'Capital Call&Distributions data'!A:A,0)),-1,2,1,1000))=0,"✔",""),"") | H55: =IFERROR(IRR(L55:AD55),"") -> 0.13229301 | I55: 48214 | J55: =YEAR(K55)-YEAR(I55) -> 0 | K55: 48214 | L55: {=IFERROR(IF(L$41<$K55,0,$F55*_xlfn.XLOOKUP($D55,'Capital Call&Distributions data'!$A:$A,INDEX('Capital Call&Distributions data'!$C:$O,0,MIN(MAX(YEAR(L$41)-YEAR($K55)+$J55+1,1),14)))),0)} -> 0 | M55: {=IFERROR(IF(M$41<$K55,0,$F55*_xlfn.XLOOKUP($D55,'Capital Call&Distributions data'!$A:$A,INDEX('Capital Call&Distributions data'!$C:$O,0,MIN(MAX(YEAR(M$41)-YEAR($K55)+$J55+1,1),14)))),0)} -> 0 | N55: {=IFERROR(IF(N$41<$K55,0,$F55*_xlfn.XLOOKUP($D55,'Capital Call&Distributions data'!$A:$A,INDEX('Capital Call&Distributions data'!$C:$O,0,MIN(MAX(YEAR(N$41)-YEAR($K55)+$J55+1,1),14)))),0)} -> 0 | O55: {=IFERROR(IF(O$41<$K55,0,$F55*_xlfn.XLOOKUP($D55,'Capital Call&Distributions data'!$A:$A,INDEX('Capital Call&Distributions data'!$C:$O,0,MIN(MAX(YEAR(O$41)-YEAR($K55)+$J55+1,1),14)))),0)} -> 0 | P55: {=IFERROR(IF(P$41<$K55,0,$F55*_xlfn.XLOOKUP($D55,'Capital Call&Distributions data'!$A:$A,INDEX('Capital Call&Distributions data'!$C:$O,0,MIN(MAX(YEAR(P$41)-YEAR($K55)+$J55+1,1),14)))),0)} -> 0 | Q55: {=IFERROR(IF(Q$41<$K55,0,$F55*_xlfn.XLOOKUP($D55,'Capital Call&Distributions data'!$A:$A,INDEX('Capital Call&Distributions data'!$C:$O,0,MIN(MAX(YEAR(Q$41)-YEAR($K55)+$J55+1,1),14)))),0)} -> 0 | R55: {=IFERROR(IF(R$41<$K55,0,$F55*_xlfn.XLOOKUP($D55,'Capital Call&Distributions data'!$A:$A,INDEX('Capital Call&Distributions data'!$C:$O,0,MIN(MAX(YEAR(R$41)-YEAR($K55)+$J55+1,1),14)))),0)} -> -2802479.6 | S55: {=IFERROR(IF(S$41<$K55,0,$F55*_xlfn.XLOOKUP($D55,'Capital Call&Distributions data'!$A:$A,INDEX('Capital Call&Distributions data'!$C:$O,0,MIN(MAX(YEAR(S$41)-YEAR($K55)+$J55+1,1),14)))),0)} -> -251220.39 | ... AU55: {=IFERROR(IF(AU$41<$K55,0,$F55*_xlfn.XLOOKUP($D55,'Capital Call&Distributions data'!$A:$A,INDEX('Capital Call&Distributions data'!$C:$O,0,MIN(MAX(YEAR(AU$41)-YEAR($K55)+$J55+1,1),14)))),0)} -> 0
C56: PE dummy | D56: =_xlfn.XLOOKUP(C56,Fondsen!B:B,Fondsen!C:C,"0",0,1) -> PE | E56: EUR | F56: 3000000 | G56: =IFERROR(IF(SUM(OFFSET(INDEX('Capital Call&Distributions data'!A:A,MATCH(D56,'Capital Call&Distributions data'!A:A,0)),-1,2,1,1000))=0,"✔",""),"") | H56: =IFERROR(IRR(L56:AD56),"") -> 0.1472451 | I56: 48214 | J56: =YEAR(K56)-YEAR(I56) -> 0 | K56: 48214 | L56: {=IFERROR(IF(L$41<$K56,0,$F56*_xlfn.XLOOKUP($D56,'Capital Call&Distributions data'!$A:$A,INDEX('Capital Call&Distributions data'!$C:$O,0,MIN(MAX(YEAR(L$41)-YEAR($K56)+$J56+1,1),14)))),0)} -> 0 | M56: {=IFERROR(IF(M$41<$K56,0,$F56*_xlfn.XLOOKUP($D56,'Capital Call&Distributions data'!$A:$A,INDEX('Capital Call&Distributions data'!$C:$O,0,MIN(MAX(YEAR(M$41)-YEAR($K56)+$J56+1,1),14)))),0)} -> 0 | N56: {=IFERROR(IF(N$41<$K56,0,$F56*_xlfn.XLOOKUP($D56,'Capital Call&Distributions data'!$A:$A,INDEX('Capital Call&Distributions data'!$C:$O,0,MIN(MAX(YEAR(N$41)-YEAR($K56)+$J56+1,1),14)))),0)} -> 0 | O56: {=IFERROR(IF(O$41<$K56,0,$F56*_xlfn.XLOOKUP($D56,'Capital Call&Distributions data'!$A:$A,INDEX('Capital Call&Distributions data'!$C:$O,0,MIN(MAX(YEAR(O$41)-YEAR($K56)+$J56+1,1),14)))),0)} -> 0 | P56: {=IFERROR(IF(P$41<$K56,0,$F56*_xlfn.XLOOKUP($D56,'Capital Call&Distributions data'!$A:$A,INDEX('Capital Call&Distributions data'!$C:$O,0,MIN(MAX(YEAR(P$41)-YEAR($K56)+$J56+1,1),14)))),0)} -> 0 | Q56: {=IFERROR(IF(Q$41<$K56,0,$F56*_xlfn.XLOOKUP($D56,'Capital Call&Distributions data'!$A:$A,INDEX('Capital Call&Distributions data'!$C:$O,0,MIN(MAX(YEAR(Q$41)-YEAR($K56)+$J56+1,1),14)))),0)} -> 0 | R56: {=IFERROR(IF(R$41<$K56,0,$F56*_xlfn.XLOOKUP($D56,'Capital Call&Distributions data'!$A:$A,INDEX('Capital Call&Distributions data'!$C:$O,0,MIN(MAX(YEAR(R$41)-YEAR($K56)+$J56+1,1),14)))),0)} -> -943851.94 | S56: {=IFERROR(IF(S$41<$K56,0,$F56*_xlfn.XLOOKUP($D56,'Capital Call&Distributions data'!$A:$A,INDEX('Capital Call&Distributions data'!$C:$O,0,MIN(MAX(YEAR(S$41)-YEAR($K56)+$J56+1,1),14)))),0)} -> -655897.11 | ... AU56: {=IFERROR(IF(AU$41<$K56,0,$F56*_xlfn.XLOOKUP($D56,'Capital Call&Distributions data'!$A:$A,INDEX('Capital Call&Distributions data'!$C:$O,0,MIN(MAX(YEAR(AU$41)-YEAR($K56)+$J56+1,1),14)))),0)} -> 0
C57: Secondaries Dummy | D57: =_xlfn.XLOOKUP(C57,Fondsen!B:B,Fondsen!C:C,"0",0,1) -> Secondaries | E57: EUR | F57: 6000000 | G57: =IFERROR(IF(SUM(OFFSET(INDEX('Capital Call&Distributions data'!A:A,MATCH(D57,'Capital Call&Distributions data'!A:A,0)),-1,2,1,1000))=0,"✔",""),"") | H57: =IFERROR(IRR(L57:AD57),"") -> 0.13229301 | I57: 48580 | J57: =YEAR(K57)-YEAR(I57) -> 0 | K57: 48580 | L57: {=IFERROR(IF(L$41<$K57,0,$F57*_xlfn.XLOOKUP($D57,'Capital Call&Distributions data'!$A:$A,INDEX('Capital Call&Distributions data'!$C:$O,0,MIN(MAX(YEAR(L$41)-YEAR($K57)+$J57+1,1),14)))),0)} -> 0 | M57: {=IFERROR(IF(M$41<$K57,0,$F57*_xlfn.XLOOKUP($D57,'Capital Call&Distributions data'!$A:$A,INDEX('Capital Call&Distributions data'!$C:$O,0,MIN(MAX(YEAR(M$41)-YEAR($K57)+$J57+1,1),14)))),0)} -> 0 | N57: {=IFERROR(IF(N$41<$K57,0,$F57*_xlfn.XLOOKUP($D57,'Capital Call&Distributions data'!$A:$A,INDEX('Capital Call&Distributions data'!$C:$O,0,MIN(MAX(YEAR(N$41)-YEAR($K57)+$J57+1,1),14)))),0)} -> 0 | O57: {=IFERROR(IF(O$41<$K57,0,$F57*_xlfn.XLOOKUP($D57,'Capital Call&Distributions data'!$A:$A,INDEX('Capital Call&Distributions data'!$C:$O,0,MIN(MAX(YEAR(O$41)-YEAR($K57)+$J57+1,1),14)))),0)} -> 0 | P57: {=IFERROR(IF(P$41<$K57,0,$F57*_xlfn.XLOOKUP($D57,'Capital Call&Distributions data'!$A:$A,INDEX('Capital Call&Distributions data'!$C:$O,0,MIN(MAX(YEAR(P$41)-YEAR($K57)+$J57+1,1),14)))),0)} -> 0 | Q57: {=IFERROR(IF(Q$41<$K57,0,$F57*_xlfn.XLOOKUP($D57,'Capital Call&Distributions data'!$A:$A,INDEX('Capital Call&Distributions data'!$C:$O,0,MIN(MAX(YEAR(Q$41)-YEAR($K57)+$J57+1,1),14)))),0)} -> 0 | R57: {=IFERROR(IF(R$41<$K57,0,$F57*_xlfn.XLOOKUP($D57,'Capital Call&Distributions data'!$A:$A,INDEX('Capital Call&Distributions data'!$C:$O,0,MIN(MAX(YEAR(R$41)-YEAR($K57)+$J57+1,1),14)))),0)} -> 0 | S57: {=IFERROR(IF(S$41<$K57,0,$F57*_xlfn.XLOOKUP($D57,'Capital Call&Distributions data'!$A:$A,INDEX('Capital Call&Distributions data'!$C:$O,0,MIN(MAX(YEAR(S$41)-YEAR($K57)+$J57+1,1),14)))),0)} -> -3193709 | ... AU57: {=IFERROR(IF(AU$41<$K57,0,$F57*_xlfn.XLOOKUP($D57,'Capital Call&Distributions data'!$A:$A,INDEX('Capital Call&Distributions data'!$C:$O,0,MIN(MAX(YEAR(AU$41)-YEAR($K57)+$J57+1,1),14)))),0)} -> 0
C58: PE dummy | D58: =_xlfn.XLOOKUP(C58,Fondsen!B:B,Fondsen!C:C,"0",0,1) -> PE | E58: EUR | F58: 2773000 | G58: =IFERROR(IF(SUM(OFFSET(INDEX('Capital Call&Distributions data'!A:A,MATCH(D58,'Capital Call&Distributions data'!A:A,0)),-1,2,1,1000))=0,"✔",""),"") | H58: =IFERROR(IRR(L58:AD58),"") -> 0.1472451 | I58: 48580 | J58: =YEAR(K58)-YEAR(I58) -> 0 | K58: 48580 | L58: {=IFERROR(IF(L$41<$K58,0,$F58*_xlfn.XLOOKUP($D58,'Capital Call&Distributions data'!$A:$A,INDEX('Capital Call&Distributions data'!$C:$O,0,MIN(MAX(YEAR(L$41)-YEAR($K58)+$J58+1,1),14)))),0)} -> 0 | M58: {=IFERROR(IF(M$41<$K58,0,$F58*_xlfn.XLOOKUP($D58,'Capital Call&Distributions data'!$A:$A,INDEX('Capital Call&Distributions data'!$C:$O,0,MIN(MAX(YEAR(M$41)-YEAR($K58)+$J58+1,1),14)))),0)} -> 0 | N58: {=IFERROR(IF(N$41<$K58,0,$F58*_xlfn.XLOOKUP($D58,'Capital Call&Distributions data'!$A:$A,INDEX('Capital Call&Distributions data'!$C:$O,0,MIN(MAX(YEAR(N$41)-YEAR($K58)+$J58+1,1),14)))),0)} -> 0 | O58: {=IFERROR(IF(O$41<$K58,0,$F58*_xlfn.XLOOKUP($D58,'Capital Call&Distributions data'!$A:$A,INDEX('Capital Call&Distributions data'!$C:$O,0,MIN(MAX(YEAR(O$41)-YEAR($K58)+$J58+1,1),14)))),0)} -> 0 | P58: {=IFERROR(IF(P$41<$K58,0,$F58*_xlfn.XLOOKUP($D58,'Capital Call&Distributions data'!$A:$A,INDEX('Capital Call&Distributions data'!$C:$O,0,MIN(MAX(YEAR(P$41)-YEAR($K58)+$J58+1,1),14)))),0)} -> 0 | Q58: {=IFERROR(IF(Q$41<$K58,0,$F58*_xlfn.XLOOKUP($D58,'Capital Call&Distributions data'!$A:$A,INDEX('Capital Call&Distributions data'!$C:$O,0,MIN(MAX(YEAR(Q$41)-YEAR($K58)+$J58+1,1),14)))),0)} -> 0 | R58: {=IFERROR(IF(R$41<$K58,0,$F58*_xlfn.XLOOKUP($D58,'Capital Call&Distributions data'!$A:$A,INDEX('Capital Call&Distributions data'!$C:$O,0,MIN(MAX(YEAR(R$41)-YEAR($K58)+$J58+1,1),14)))),0)} -> 0 | S58: {=IFERROR(IF(S$41<$K58,0,$F58*_xlfn.XLOOKUP($D58,'Capital Call&Distributions data'!$A:$A,INDEX('Capital Call&Distributions data'!$C:$O,0,MIN(MAX(YEAR(S$41)-YEAR($K58)+$J58+1,1),14)))),0)} -> -872433.81 | ... AU58: {=IFERROR(IF(AU$41<$K58,0,$F58*_xlfn.XLOOKUP($D58,'Capital Call&Distributions data'!$A:$A,INDEX('Capital Call&Distributions data'!$C:$O,0,MIN(MAX(YEAR(AU$41)-YEAR($K58)+$J58+1,1),14)))),0)} -> 0
D59: =_xlfn.XLOOKUP(C59,Fondsen!B:B,Fondsen!C:C,"0",0,1) -> 0 | E59: EUR | G59: =IFERROR(IF(SUM(OFFSET(INDEX('Capital Call&Distributions data'!A:A,MATCH(D59,'Capital Call&Distributions data'!A:A,0)),-1,2,1,1000))=0,"✔",""),"") | H59: =IFERROR(IRR(L59:AD59),"") | I59: 47484 | J59: =YEAR(K59)-YEAR(I59) -> 0 | K59: 47484 | L59: {=IFERROR(IF(L$41<$K59,0,$F59*_xlfn.XLOOKUP($D59,'Capital Call&Distributions data'!$A:$A,INDEX('Capital Call&Distributions data'!$C:$O,0,MIN(MAX(YEAR(L$41)-YEAR($K59)+$J59+1,1),14)))),0)} -> 0 | M59: {=IFERROR(IF(M$41<$K59,0,$F59*_xlfn.XLOOKUP($D59,'Capital Call&Distributions data'!$A:$A,INDEX('Capital Call&Distributions data'!$C:$O,0,MIN(MAX(YEAR(M$41)-YEAR($K59)+$J59+1,1),14)))),0)} -> 0 | N59: {=IFERROR(IF(N$41<$K59,0,$F59*_xlfn.XLOOKUP($D59,'Capital Call&Distributions data'!$A:$A,INDEX('Capital Call&Distributions data'!$C:$O,0,MIN(MAX(YEAR(N$41)-YEAR($K59)+$J59+1,1),14)))),0)} -> 0 | O59: {=IFERROR(IF(O$41<$K59,0,$F59*_xlfn.XLOOKUP($D59,'Capital Call&Distributions data'!$A:$A,INDEX('Capital Call&Distributions data'!$C:$O,0,MIN(MAX(YEAR(O$41)-YEAR($K59)+$J59+1,1),14)))),0)} -> 0 | P59: {=IFERROR(IF(P$41<$K59,0,$F59*_xlfn.XLOOKUP($D59,'Capital Call&Distributions data'!$A:$A,INDEX('Capital Call&Distributions data'!$C:$O,0,MIN(MAX(YEAR(P$41)-YEAR($K59)+$J59+1,1),14)))),0)} -> 0 | Q59: {=IFERROR(IF(Q$41<$K59,0,$F59*_xlfn.XLOOKUP($D59,'Capital Call&Distributions data'!$A:$A,INDEX('Capital Call&Distributions data'!$C:$O,0,MIN(MAX(YEAR(Q$41)-YEAR($K59)+$J59+1,1),14)))),0)} -> 0 | R59: {=IFERROR(IF(R$41<$K59,0,$F59*_xlfn.XLOOKUP($D59,'Capital Call&Distributions data'!$A:$A,INDEX('Capital Call&Distributions data'!$C:$O,0,MIN(MAX(YEAR(R$41)-YEAR($K59)+$J59+1,1),14)))),0)} -> 0 | S59: {=IFERROR(IF(S$41<$K59,0,$F59*_xlfn.XLOOKUP($D59,'Capital Call&Distributions data'!$A:$A,INDEX('Capital Call&Distributions data'!$C:$O,0,MIN(MAX(YEAR(S$41)-YEAR($K59)+$J59+1,1),14)))),0)} -> 0 | ... AU59: {=IFERROR(IF(AU$41<$K59,0,$F59*_xlfn.XLOOKUP($D59,'Capital Call&Distributions data'!$A:$A,INDEX('Capital Call&Distributions data'!$C:$O,0,MIN(MAX(YEAR(AU$41)-YEAR($K59)+$J59+1,1),14)))),0)} -> 0
D60: =_xlfn.XLOOKUP(C60,Fondsen!B:B,Fondsen!C:C,"0",0,1) -> 0 | E60: EUR | G60: =IFERROR(IF(SUM(OFFSET(INDEX('Capital Call&Distributions data'!A:A,MATCH(D60,'Capital Call&Distributions data'!A:A,0)),-1,2,1,1000))=0,"✔",""),"") | H60: =IFERROR(IRR(L60:AD60),"") | I60: 47484 | J60: =YEAR(K60)-YEAR(I60) -> 0 | K60: 47484 | L60: {=IFERROR(IF(L$41<$K60,0,$F60*_xlfn.XLOOKUP($D60,'Capital Call&Distributions data'!$A:$A,INDEX('Capital Call&Distributions data'!$C:$O,0,MIN(MAX(YEAR(L$41)-YEAR($K60)+$J60+1,1),14)))),0)} -> 0 | M60: {=IFERROR(IF(M$41<$K60,0,$F60*_xlfn.XLOOKUP($D60,'Capital Call&Distributions data'!$A:$A,INDEX('Capital Call&Distributions data'!$C:$O,0,MIN(MAX(YEAR(M$41)-YEAR($K60)+$J60+1,1),14)))),0)} -> 0 | N60: {=IFERROR(IF(N$41<$K60,0,$F60*_xlfn.XLOOKUP($D60,'Capital Call&Distributions data'!$A:$A,INDEX('Capital Call&Distributions data'!$C:$O,0,MIN(MAX(YEAR(N$41)-YEAR($K60)+$J60+1,1),14)))),0)} -> 0 | O60: {=IFERROR(IF(O$41<$K60,0,$F60*_xlfn.XLOOKUP($D60,'Capital Call&Distributions data'!$A:$A,INDEX('Capital Call&Distributions data'!$C:$O,0,MIN(MAX(YEAR(O$41)-YEAR($K60)+$J60+1,1),14)))),0)} -> 0 | P60: {=IFERROR(IF(P$41<$K60,0,$F60*_xlfn.XLOOKUP($D60,'Capital Call&Distributions data'!$A:$A,INDEX('Capital Call&Distributions data'!$C:$O,0,MIN(MAX(YEAR(P$41)-YEAR($K60)+$J60+1,1),14)))),0)} -> 0 | Q60: {=IFERROR(IF(Q$41<$K60,0,$F60*_xlfn.XLOOKUP($D60,'Capital Call&Distributions data'!$A:$A,INDEX('Capital Call&Distributions data'!$C:$O,0,MIN(MAX(YEAR(Q$41)-YEAR($K60)+$J60+1,1),14)))),0)} -> 0 | R60: {=IFERROR(IF(R$41<$K60,0,$F60*_xlfn.XLOOKUP($D60,'Capital Call&Distributions data'!$A:$A,INDEX('Capital Call&Distributions data'!$C:$O,0,MIN(MAX(YEAR(R$41)-YEAR($K60)+$J60+1,1),14)))),0)} -> 0 | S60: {=IFERROR(IF(S$41<$K60,0,$F60*_xlfn.XLOOKUP($D60,'Capital Call&Distributions data'!$A:$A,INDEX('Capital Call&Distributions data'!$C:$O,0,MIN(MAX(YEAR(S$41)-YEAR($K60)+$J60+1,1),14)))),0)} -> 0 | ... AU60: {=IFERROR(IF(AU$41<$K60,0,$F60*_xlfn.XLOOKUP($D60,'Capital Call&Distributions data'!$A:$A,INDEX('Capital Call&Distributions data'!$C:$O,0,MIN(MAX(YEAR(AU$41)-YEAR($K60)+$J60+1,1),14)))),0)} -> 0
D61: =_xlfn.XLOOKUP(C61,Fondsen!B:B,Fondsen!C:C,"0",0,1) -> 0 | E61: EUR | G61: =IFERROR(IF(SUM(OFFSET(INDEX('Capital Call&Distributions data'!A:A,MATCH(D61,'Capital Call&Distributions data'!A:A,0)),-1,2,1,1000))=0,"✔",""),"") | H61: =IFERROR(IRR(L61:AD61),"") | I61: 47849 | J61: =YEAR(K61)-YEAR(I61) -> 0 | K61: 47849 | L61: {=IFERROR(IF(L$41<$K61,0,$F61*_xlfn.XLOOKUP($D61,'Capital Call&Distributions data'!$A:$A,INDEX('Capital Call&Distributions data'!$C:$O,0,MIN(MAX(YEAR(L$41)-YEAR($K61)+$J61+1,1),14)))),0)} -> 0 | M61: {=IFERROR(IF(M$41<$K61,0,$F61*_xlfn.XLOOKUP($D61,'Capital Call&Distributions data'!$A:$A,INDEX('Capital Call&Distributions data'!$C:$O,0,MIN(MAX(YEAR(M$41)-YEAR($K61)+$J61+1,1),14)))),0)} -> 0 | N61: {=IFERROR(IF(N$41<$K61,0,$F61*_xlfn.XLOOKUP($D61,'Capital Call&Distributions data'!$A:$A,INDEX('Capital Call&Distributions data'!$C:$O,0,MIN(MAX(YEAR(N$41)-YEAR($K61)+$J61+1,1),14)))),0)} -> 0 | O61: {=IFERROR(IF(O$41<$K61,0,$F61*_xlfn.XLOOKUP($D61,'Capital Call&Distributions data'!$A:$A,INDEX('Capital Call&Distributions data'!$C:$O,0,MIN(MAX(YEAR(O$41)-YEAR($K61)+$J61+1,1),14)))),0)} -> 0 | P61: {=IFERROR(IF(P$41<$K61,0,$F61*_xlfn.XLOOKUP($D61,'Capital Call&Distributions data'!$A:$A,INDEX('Capital Call&Distributions data'!$C:$O,0,MIN(MAX(YEAR(P$41)-YEAR($K61)+$J61+1,1),14)))),0)} -> 0 | Q61: {=IFERROR(IF(Q$41<$K61,0,$F61*_xlfn.XLOOKUP($D61,'Capital Call&Distributions data'!$A:$A,INDEX('Capital Call&Distributions data'!$C:$O,0,MIN(MAX(YEAR(Q$41)-YEAR($K61)+$J61+1,1),14)))),0)} -> 0 | R61: {=IFERROR(IF(R$41<$K61,0,$F61*_xlfn.XLOOKUP($D61,'Capital Call&Distributions data'!$A:$A,INDEX('Capital Call&Distributions data'!$C:$O,0,MIN(MAX(YEAR(R$41)-YEAR($K61)+$J61+1,1),14)))),0)} -> 0 | S61: {=IFERROR(IF(S$41<$K61,0,$F61*_xlfn.XLOOKUP($D61,'Capital Call&Distributions data'!$A:$A,INDEX('Capital Call&Distributions data'!$C:$O,0,MIN(MAX(YEAR(S$41)-YEAR($K61)+$J61+1,1),14)))),0)} -> 0 | ... AU61: {=IFERROR(IF(AU$41<$K61,0,$F61*_xlfn.XLOOKUP($D61,'Capital Call&Distributions data'!$A:$A,INDEX('Capital Call&Distributions data'!$C:$O,0,MIN(MAX(YEAR(AU$41)-YEAR($K61)+$J61+1,1),14)))),0)} -> 0
D62: =_xlfn.XLOOKUP(C62,Fondsen!B:B,Fondsen!C:C,"0",0,1) -> 0 | E62: EUR | G62: =IFERROR(IF(SUM(OFFSET(INDEX('Capital Call&Distributions data'!A:A,MATCH(D62,'Capital Call&Distributions data'!A:A,0)),-1,2,1,1000))=0,"✔",""),"") | H62: =IFERROR(IRR(L62:AD62),"") | I62: 47849 | J62: =YEAR(K62)-YEAR(I62) -> 0 | K62: 47849 | L62: {=IFERROR(IF(L$41<$K62,0,$F62*_xlfn.XLOOKUP($D62,'Capital Call&Distributions data'!$A:$A,INDEX('Capital Call&Distributions data'!$C:$O,0,MIN(MAX(YEAR(L$41)-YEAR($K62)+$J62+1,1),14)))),0)} -> 0 | M62: {=IFERROR(IF(M$41<$K62,0,$F62*_xlfn.XLOOKUP($D62,'Capital Call&Distributions data'!$A:$A,INDEX('Capital Call&Distributions data'!$C:$O,0,MIN(MAX(YEAR(M$41)-YEAR($K62)+$J62+1,1),14)))),0)} -> 0 | N62: {=IFERROR(IF(N$41<$K62,0,$F62*_xlfn.XLOOKUP($D62,'Capital Call&Distributions data'!$A:$A,INDEX('Capital Call&Distributions data'!$C:$O,0,MIN(MAX(YEAR(N$41)-YEAR($K62)+$J62+1,1),14)))),0)} -> 0 | O62: {=IFERROR(IF(O$41<$K62,0,$F62*_xlfn.XLOOKUP($D62,'Capital Call&Distributions data'!$A:$A,INDEX('Capital Call&Distributions data'!$C:$O,0,MIN(MAX(YEAR(O$41)-YEAR($K62)+$J62+1,1),14)))),0)} -> 0 | P62: {=IFERROR(IF(P$41<$K62,0,$F62*_xlfn.XLOOKUP($D62,'Capital Call&Distributions data'!$A:$A,INDEX('Capital Call&Distributions data'!$C:$O,0,MIN(MAX(YEAR(P$41)-YEAR($K62)+$J62+1,1),14)))),0)} -> 0 | Q62: {=IFERROR(IF(Q$41<$K62,0,$F62*_xlfn.XLOOKUP($D62,'Capital Call&Distributions data'!$A:$A,INDEX('Capital Call&Distributions data'!$C:$O,0,MIN(MAX(YEAR(Q$41)-YEAR($K62)+$J62+1,1),14)))),0)} -> 0 | R62: {=IFERROR(IF(R$41<$K62,0,$F62*_xlfn.XLOOKUP($D62,'Capital Call&Distributions data'!$A:$A,INDEX('Capital Call&Distributions data'!$C:$O,0,MIN(MAX(YEAR(R$41)-YEAR($K62)+$J62+1,1),14)))),0)} -> 0 | S62: {=IFERROR(IF(S$41<$K62,0,$F62*_xlfn.XLOOKUP($D62,'Capital Call&Distributions data'!$A:$A,INDEX('Capital Call&Distributions data'!$C:$O,0,MIN(MAX(YEAR(S$41)-YEAR($K62)+$J62+1,1),14)))),0)} -> 0 | ... AU62: {=IFERROR(IF(AU$41<$K62,0,$F62*_xlfn.XLOOKUP($D62,'Capital Call&Distributions data'!$A:$A,INDEX('Capital Call&Distributions data'!$C:$O,0,MIN(MAX(YEAR(AU$41)-YEAR($K62)+$J62+1,1),14)))),0)} -> 0
D63: =_xlfn.XLOOKUP(C63,Fondsen!B:B,Fondsen!C:C,"0",0,1) -> 0 | E63: EUR | G63: =IFERROR(IF(SUM(OFFSET(INDEX('Capital Call&Distributions data'!A:A,MATCH(D63,'Capital Call&Distributions data'!A:A,0)),-1,2,1,1000))=0,"✔",""),"") | H63: =IFERROR(IRR(L63:AD63),"") | I63: 47849 | J63: =YEAR(K63)-YEAR(I63) -> 0 | K63: 47849 | L63: {=IFERROR(IF(L$41<$K63,0,$F63*_xlfn.XLOOKUP($D63,'Capital Call&Distributions data'!$A:$A,INDEX('Capital Call&Distributions data'!$C:$O,0,MIN(MAX(YEAR(L$41)-YEAR($K63)+$J63+1,1),14)))),0)} -> 0 | M63: {=IFERROR(IF(M$41<$K63,0,$F63*_xlfn.XLOOKUP($D63,'Capital Call&Distributions data'!$A:$A,INDEX('Capital Call&Distributions data'!$C:$O,0,MIN(MAX(YEAR(M$41)-YEAR($K63)+$J63+1,1),14)))),0)} -> 0 | N63: {=IFERROR(IF(N$41<$K63,0,$F63*_xlfn.XLOOKUP($D63,'Capital Call&Distributions data'!$A:$A,INDEX('Capital Call&Distributions data'!$C:$O,0,MIN(MAX(YEAR(N$41)-YEAR($K63)+$J63+1,1),14)))),0)} -> 0 | O63: {=IFERROR(IF(O$41<$K63,0,$F63*_xlfn.XLOOKUP($D63,'Capital Call&Distributions data'!$A:$A,INDEX('Capital Call&Distributions data'!$C:$O,0,MIN(MAX(YEAR(O$41)-YEAR($K63)+$J63+1,1),14)))),0)} -> 0 | P63: {=IFERROR(IF(P$41<$K63,0,$F63*_xlfn.XLOOKUP($D63,'Capital Call&Distributions data'!$A:$A,INDEX('Capital Call&Distributions data'!$C:$O,0,MIN(MAX(YEAR(P$41)-YEAR($K63)+$J63+1,1),14)))),0)} -> 0 | Q63: {=IFERROR(IF(Q$41<$K63,0,$F63*_xlfn.XLOOKUP($D63,'Capital Call&Distributions data'!$A:$A,INDEX('Capital Call&Distributions data'!$C:$O,0,MIN(MAX(YEAR(Q$41)-YEAR($K63)+$J63+1,1),14)))),0)} -> 0 | R63: {=IFERROR(IF(R$41<$K63,0,$F63*_xlfn.XLOOKUP($D63,'Capital Call&Distributions data'!$A:$A,INDEX('Capital Call&Distributions data'!$C:$O,0,MIN(MAX(YEAR(R$41)-YEAR($K63)+$J63+1,1),14)))),0)} -> 0 | S63: {=IFERROR(IF(S$41<$K63,0,$F63*_xlfn.XLOOKUP($D63,'Capital Call&Distributions data'!$A:$A,INDEX('Capital Call&Distributions data'!$C:$O,0,MIN(MAX(YEAR(S$41)-YEAR($K63)+$J63+1,1),14)))),0)} -> 0 | ... AU63: {=IFERROR(IF(AU$41<$K63,0,$F63*_xlfn.XLOOKUP($D63,'Capital Call&Distributions data'!$A:$A,INDEX('Capital Call&Distributions data'!$C:$O,0,MIN(MAX(YEAR(AU$41)-YEAR($K63)+$J63+1,1),14)))),0)} -> 0
D64: =_xlfn.XLOOKUP(C64,Fondsen!B:B,Fondsen!C:C,"0",0,1) -> 0 | E64: EUR | G64: =IFERROR(IF(SUM(OFFSET(INDEX('Capital Call&Distributions data'!A:A,MATCH(D64,'Capital Call&Distributions data'!A:A,0)),-1,2,1,1000))=0,"✔",""),"") | H64: =IFERROR(IRR(L64:AD64),"") | I64: 48214 | J64: =YEAR(K64)-YEAR(I64) -> 0 | K64: 48214 | L64: {=IFERROR(IF(L$41<$K64,0,$F64*_xlfn.XLOOKUP($D64,'Capital Call&Distributions data'!$A:$A,INDEX('Capital Call&Distributions data'!$C:$O,0,MIN(MAX(YEAR(L$41)-YEAR($K64)+$J64+1,1),14)))),0)} -> 0 | M64: {=IFERROR(IF(M$41<$K64,0,$F64*_xlfn.XLOOKUP($D64,'Capital Call&Distributions data'!$A:$A,INDEX('Capital Call&Distributions data'!$C:$O,0,MIN(MAX(YEAR(M$41)-YEAR($K64)+$J64+1,1),14)))),0)} -> 0 | N64: {=IFERROR(IF(N$41<$K64,0,$F64*_xlfn.XLOOKUP($D64,'Capital Call&Distributions data'!$A:$A,INDEX('Capital Call&Distributions data'!$C:$O,0,MIN(MAX(YEAR(N$41)-YEAR($K64)+$J64+1,1),14)))),0)} -> 0 | O64: {=IFERROR(IF(O$41<$K64,0,$F64*_xlfn.XLOOKUP($D64,'Capital Call&Distributions data'!$A:$A,INDEX('Capital Call&Distributions data'!$C:$O,0,MIN(MAX(YEAR(O$41)-YEAR($K64)+$J64+1,1),14)))),0)} -> 0 | P64: {=IFERROR(IF(P$41<$K64,0,$F64*_xlfn.XLOOKUP($D64,'Capital Call&Distributions data'!$A:$A,INDEX('Capital Call&Distributions data'!$C:$O,0,MIN(MAX(YEAR(P$41)-YEAR($K64)+$J64+1,1),14)))),0)} -> 0 | Q64: {=IFERROR(IF(Q$41<$K64,0,$F64*_xlfn.XLOOKUP($D64,'Capital Call&Distributions data'!$A:$A,INDEX('Capital Call&Distributions data'!$C:$O,0,MIN(MAX(YEAR(Q$41)-YEAR($K64)+$J64+1,1),14)))),0)} -> 0 | R64: {=IFERROR(IF(R$41<$K64,0,$F64*_xlfn.XLOOKUP($D64,'Capital Call&Distributions data'!$A:$A,INDEX('Capital Call&Distributions data'!$C:$O,0,MIN(MAX(YEAR(R$41)-YEAR($K64)+$J64+1,1),14)))),0)} -> 0 | S64: {=IFERROR(IF(S$41<$K64,0,$F64*_xlfn.XLOOKUP($D64,'Capital Call&Distributions data'!$A:$A,INDEX('Capital Call&Distributions data'!$C:$O,0,MIN(MAX(YEAR(S$41)-YEAR($K64)+$J64+1,1),14)))),0)} -> 0 | ... AU64: {=IFERROR(IF(AU$41<$K64,0,$F64*_xlfn.XLOOKUP($D64,'Capital Call&Distributions data'!$A:$A,INDEX('Capital Call&Distributions data'!$C:$O,0,MIN(MAX(YEAR(AU$41)-YEAR($K64)+$J64+1,1),14)))),0)} -> 0
D65: =_xlfn.XLOOKUP(C65,Fondsen!B:B,Fondsen!C:C,"0",0,1) -> 0 | E65: EUR | G65: =IFERROR(IF(SUM(OFFSET(INDEX('Capital Call&Distributions data'!A:A,MATCH(D65,'Capital Call&Distributions data'!A:A,0)),-1,2,1,1000))=0,"✔",""),"") | H65: =IFERROR(IRR(L65:AD65),"") | I65: 48214 | J65: =YEAR(K65)-YEAR(I65) -> 0 | K65: 48214 | L65: {=IFERROR(IF(L$41<$K65,0,$F65*_xlfn.XLOOKUP($D65,'Capital Call&Distributions data'!$A:$A,INDEX('Capital Call&Distributions data'!$C:$O,0,MIN(MAX(YEAR(L$41)-YEAR($K65)+$J65+1,1),14)))),0)} -> 0 | M65: {=IFERROR(IF(M$41<$K65,0,$F65*_xlfn.XLOOKUP($D65,'Capital Call&Distributions data'!$A:$A,INDEX('Capital Call&Distributions data'!$C:$O,0,MIN(MAX(YEAR(M$41)-YEAR($K65)+$J65+1,1),14)))),0)} -> 0 | N65: {=IFERROR(IF(N$41<$K65,0,$F65*_xlfn.XLOOKUP($D65,'Capital Call&Distributions data'!$A:$A,INDEX('Capital Call&Distributions data'!$C:$O,0,MIN(MAX(YEAR(N$41)-YEAR($K65)+$J65+1,1),14)))),0)} -> 0 | O65: {=IFERROR(IF(O$41<$K65,0,$F65*_xlfn.XLOOKUP($D65,'Capital Call&Distributions data'!$A:$A,INDEX('Capital Call&Distributions data'!$C:$O,0,MIN(MAX(YEAR(O$41)-YEAR($K65)+$J65+1,1),14)))),0)} -> 0 | P65: {=IFERROR(IF(P$41<$K65,0,$F65*_xlfn.XLOOKUP($D65,'Capital Call&Distributions data'!$A:$A,INDEX('Capital Call&Distributions data'!$C:$O,0,MIN(MAX(YEAR(P$41)-YEAR($K65)+$J65+1,1),14)))),0)} -> 0 | Q65: {=IFERROR(IF(Q$41<$K65,0,$F65*_xlfn.XLOOKUP($D65,'Capital Call&Distributions data'!$A:$A,INDEX('Capital Call&Distributions data'!$C:$O,0,MIN(MAX(YEAR(Q$41)-YEAR($K65)+$J65+1,1),14)))),0)} -> 0 | R65: {=IFERROR(IF(R$41<$K65,0,$F65*_xlfn.XLOOKUP($D65,'Capital Call&Distributions data'!$A:$A,INDEX('Capital Call&Distributions data'!$C:$O,0,MIN(MAX(YEAR(R$41)-YEAR($K65)+$J65+1,1),14)))),0)} -> 0 | S65: {=IFERROR(IF(S$41<$K65,0,$F65*_xlfn.XLOOKUP($D65,'Capital Call&Distributions data'!$A:$A,INDEX('Capital Call&Distributions data'!$C:$O,0,MIN(MAX(YEAR(S$41)-YEAR($K65)+$J65+1,1),14)))),0)} -> 0 | ... AU65: {=IFERROR(IF(AU$41<$K65,0,$F65*_xlfn.XLOOKUP($D65,'Capital Call&Distributions data'!$A:$A,INDEX('Capital Call&Distributions data'!$C:$O,0,MIN(MAX(YEAR(AU$41)-YEAR($K65)+$J65+1,1),14)))),0)} -> 0
D66: =_xlfn.XLOOKUP(C66,Fondsen!B:B,Fondsen!C:C,"0",0,1) -> 0 | E66: EUR | G66: =IFERROR(IF(SUM(OFFSET(INDEX('Capital Call&Distributions data'!A:A,MATCH(D66,'Capital Call&Distributions data'!A:A,0)),-1,2,1,1000))=0,"✔",""),"") | H66: =IFERROR(IRR(L66:AD66),"") | I66: 48214 | J66: =YEAR(K66)-YEAR(I66) -> 0 | K66: 48214 | L66: {=IFERROR(IF(L$41<$K66,0,$F66*_xlfn.XLOOKUP($D66,'Capital Call&Distributions data'!$A:$A,INDEX('Capital Call&Distributions data'!$C:$O,0,MIN(MAX(YEAR(L$41)-YEAR($K66)+$J66+1,1),14)))),0)} -> 0 | M66: {=IFERROR(IF(M$41<$K66,0,$F66*_xlfn.XLOOKUP($D66,'Capital Call&Distributions data'!$A:$A,INDEX('Capital Call&Distributions data'!$C:$O,0,MIN(MAX(YEAR(M$41)-YEAR($K66)+$J66+1,1),14)))),0)} -> 0 | N66: {=IFERROR(IF(N$41<$K66,0,$F66*_xlfn.XLOOKUP($D66,'Capital Call&Distributions data'!$A:$A,INDEX('Capital Call&Distributions data'!$C:$O,0,MIN(MAX(YEAR(N$41)-YEAR($K66)+$J66+1,1),14)))),0)} -> 0 | O66: {=IFERROR(IF(O$41<$K66,0,$F66*_xlfn.XLOOKUP($D66,'Capital Call&Distributions data'!$A:$A,INDEX('Capital Call&Distributions data'!$C:$O,0,MIN(MAX(YEAR(O$41)-YEAR($K66)+$J66+1,1),14)))),0)} -> 0 | P66: {=IFERROR(IF(P$41<$K66,0,$F66*_xlfn.XLOOKUP($D66,'Capital Call&Distributions data'!$A:$A,INDEX('Capital Call&Distributions data'!$C:$O,0,MIN(MAX(YEAR(P$41)-YEAR($K66)+$J66+1,1),14)))),0)} -> 0 | Q66: {=IFERROR(IF(Q$41<$K66,0,$F66*_xlfn.XLOOKUP($D66,'Capital Call&Distributions data'!$A:$A,INDEX('Capital Call&Distributions data'!$C:$O,0,MIN(MAX(YEAR(Q$41)-YEAR($K66)+$J66+1,1),14)))),0)} -> 0 | R66: {=IFERROR(IF(R$41<$K66,0,$F66*_xlfn.XLOOKUP($D66,'Capital Call&Distributions data'!$A:$A,INDEX('Capital Call&Distributions data'!$C:$O,0,MIN(MAX(YEAR(R$41)-YEAR($K66)+$J66+1,1),14)))),0)} -> 0 | S66: {=IFERROR(IF(S$41<$K66,0,$F66*_xlfn.XLOOKUP($D66,'Capital Call&Distributions data'!$A:$A,INDEX('Capital Call&Distributions data'!$C:$O,0,MIN(MAX(YEAR(S$41)-YEAR($K66)+$J66+1,1),14)))),0)} -> 0 | ... AU66: {=IFERROR(IF(AU$41<$K66,0,$F66*_xlfn.XLOOKUP($D66,'Capital Call&Distributions data'!$A:$A,INDEX('Capital Call&Distributions data'!$C:$O,0,MIN(MAX(YEAR(AU$41)-YEAR($K66)+$J66+1,1),14)))),0)} -> 0
D67: =_xlfn.XLOOKUP(C67,Fondsen!B:B,Fondsen!C:C,"0",0,1) -> 0 | E67: EUR | G67: =IFERROR(IF(SUM(OFFSET(INDEX('Capital Call&Distributions data'!A:A,MATCH(D67,'Capital Call&Distributions data'!A:A,0)),-1,2,1,1000))=0,"✔",""),"") | H67: =IFERROR(IRR(L67:AD67),"") | I67: 45658 | J67: =YEAR(K67)-YEAR(I67) -> 0 | K67: 45658 | L67: {=IFERROR(IF(L$41<$K67,0,$F67*_xlfn.XLOOKUP($D67,'Capital Call&Distributions data'!$A:$A,INDEX('Capital Call&Distributions data'!$C:$O,0,MIN(MAX(YEAR(L$41)-YEAR($K67)+$J67+1,1),14)))),0)} -> 0 | M67: {=IFERROR(IF(M$41<$K67,0,$F67*_xlfn.XLOOKUP($D67,'Capital Call&Distributions data'!$A:$A,INDEX('Capital Call&Distributions data'!$C:$O,0,MIN(MAX(YEAR(M$41)-YEAR($K67)+$J67+1,1),14)))),0)} -> 0 | N67: {=IFERROR(IF(N$41<$K67,0,$F67*_xlfn.XLOOKUP($D67,'Capital Call&Distributions data'!$A:$A,INDEX('Capital Call&Distributions data'!$C:$O,0,MIN(MAX(YEAR(N$41)-YEAR($K67)+$J67+1,1),14)))),0)} -> 0 | O67: {=IFERROR(IF(O$41<$K67,0,$F67*_xlfn.XLOOKUP($D67,'Capital Call&Distributions data'!$A:$A,INDEX('Capital Call&Distributions data'!$C:$O,0,MIN(MAX(YEAR(O$41)-YEAR($K67)+$J67+1,1),14)))),0)} -> 0 | P67: {=IFERROR(IF(P$41<$K67,0,$F67*_xlfn.XLOOKUP($D67,'Capital Call&Distributions data'!$A:$A,INDEX('Capital Call&Distributions data'!$C:$O,0,MIN(MAX(YEAR(P$41)-YEAR($K67)+$J67+1,1),14)))),0)} -> 0 | Q67: {=IFERROR(IF(Q$41<$K67,0,$F67*_xlfn.XLOOKUP($D67,'Capital Call&Distributions data'!$A:$A,INDEX('Capital Call&Distributions data'!$C:$O,0,MIN(MAX(YEAR(Q$41)-YEAR($K67)+$J67+1,1),14)))),0)} -> 0 | R67: {=IFERROR(IF(R$41<$K67,0,$F67*_xlfn.XLOOKUP($D67,'Capital Call&Distributions data'!$A:$A,INDEX('Capital Call&Distributions data'!$C:$O,0,MIN(MAX(YEAR(R$41)-YEAR($K67)+$J67+1,1),14)))),0)} -> 0 | S67: {=IFERROR(IF(S$41<$K67,0,$F67*_xlfn.XLOOKUP($D67,'Capital Call&Distributions data'!$A:$A,INDEX('Capital Call&Distributions data'!$C:$O,0,MIN(MAX(YEAR(S$41)-YEAR($K67)+$J67+1,1),14)))),0)} -> 0 | ... AU67: {=IFERROR(IF(AU$41<$K67,0,$F67*_xlfn.XLOOKUP($D67,'Capital Call&Distributions data'!$A:$A,INDEX('Capital Call&Distributions data'!$C:$O,0,MIN(MAX(YEAR(AU$41)-YEAR($K67)+$J67+1,1),14)))),0)} -> 0
